<?xml version="1.0" ?>
<!-- =================================================================================== -->
<!-- |    This document was autogenerated by xacro from urdf/genie.robot.xacro         | -->
<!-- |    EDITING THIS FILE BY HAND IS NOT RECOMMENDED                                 | -->
<!-- =================================================================================== -->
<robot name="genie">
  <!-- robot -->
  <!-- Material Definition -->
  <material name="black">
    <color rgba="0.0 0.0 0.0 1.0"/>
  </material>
  <material name="blue">
    <color rgba="0.0 0.0 0.8 1.0"/>
  </material>
  <material name="green">
    <color rgba="0.0 1.0 0.0 1.0"/>
  </material>
  <material name="grey">
    <color rgba="0.2 0.2 0.2 1.0"/>
  </material>
  <material name="orange">
    <color rgba="1.0 0.4235294117647059 0.0392156862745098 1.0"/>
  </material>
  <material name="brown">
    <color rgba="0.8705882352941177 0.8117647058823529 0.7647058823529411 1.0"/>
  </material>
  <material name="red">
    <color rgba="0.8 0.0 0.0 1.0"/>
  </material>
  <material name="white">
    <color rgba="1.0 1.0 1.0 1.0"/>
  </material>
  <!-- transparent is not working properly -->
  <material name="transparent">
    <color rgba="1.0 1.0 1.0 0.999"/>
  </material>
  <material name="default">
    <color rgba="0.752941176470588 0.752941176470588 0.752941176470588 1"/>
  </material>
  <!-- links -->
  <link name="base_link">
    <inertial>
      <origin rpy="0.0 0.0 0.0" xyz="-0.0134486971267798 0.00152103941353612 -0.0320076754329413"/>
      <mass value="23.2085382238952"/>
      <inertia ixx="0.386955641760608" ixy="0.000135417314593726" ixz="0.00669301645720665" iyy="0.366800407621218" iyz="0.000105713634260505" izz="0.546852919828475"/>
    </inertial>
    <visual>
      <geometry>
        <mesh filename="package://genie_robot_description/meshes/G1/base_link.fbx"/>
      </geometry>
      <origin rpy="0.0 0.0 0.0" xyz="0.0 0.0 0.0"/>
    </visual>
    <!-- <collision>
        <origin
          rpy="0.0 0.0 0.0"
          xyz="-0.10913086 0.0 0.51171875" />
        <geometry>
          <box size="0.29833984 0.3376392 1.0" />
        </geometry>
      </collision>
      <collision>
        <origin
          rpy="0.0 0.0 0.0"
          xyz="0.0 0.0 0.15" />
        <geometry>
          <box size="0.5996094 0.449 0.30273438" />
        </geometry>
      </collision> -->
  </link>
  <link name="body_link1">
    <inertial>
      <origin rpy="0.0 0.0 0.0" xyz="0.0338351537064605 -0.00248044044451858 0.000838431095422365"/>
      <mass value="3.26275452360108"/>
      <inertia ixx="0.0128301877197417" ixy="8.24967996575627e-06" ixz="1.38254543337324e-05" iyy="0.006104110250297" iyz="-7.99392548994692e-06" izz="0.0111721084996867"/>
    </inertial>
    <visual>
      <geometry>
        <mesh filename="package://genie_robot_description/meshes/G1/body_link1.fbx"/>
      </geometry>
      <origin rpy="0.0 0.0 0.0" xyz="0.0 0.0 0.0"/>
    </visual>
    <!-- <collision>
        <origin
          rpy="0.0 0.0 0.0"
          xyz="0.10278320000000002 0.1 -0.013671875" />
        <geometry>
          <box size="0.16064453 0.05555534399999999 0.1328125" />
        </geometry>
      </collision>
      <collision>
        <origin
          rpy="0.0 0.0 0.0"
          xyz="0.10180664 -0.1 0.0" />
        <geometry>
          <box size="0.16259765999999998 0.04375648500000001 0.16015625" />
        </geometry>
      </collision> -->
  </link>
  <link name="body_link2">
    <inertial>
      <origin rpy="0.0 0.0 0.0" xyz="0.193733558855111 -0.000484180179482319 -0.00124011422952511"/>
      <mass value="7.53199207979272"/>
      <inertia ixx="0.016546682835947" ixy="0.000274441382484697" ixz="0.00102757387076422" iyy="0.0445441227006132" iyz="-0.000236858278708531" izz="0.0402036337794082"/>
    </inertial>
    <visual>
      <geometry>
        <mesh filename="package://genie_robot_description/meshes/G1/body_link2.fbx"/>
      </geometry>
      <origin rpy="0.0 0.0 -1.5707963267948966" xyz="0.0 0.0 0.0"/>
    </visual>
    <!-- <collision>
        <origin
          rpy="0 0 0"
          xyz="0.0068359375 -0.00034356117 0.0" />
        <geometry>
          <cylinder radius="0.09662318" length="0.08697056999999997" />
        </geometry>
      </collision>
      <collision>
        <origin
          xyz="0.0068359375 -0.00034356117 0.043485284999999985" />
        <geometry>
          <sphere radius="0.09662318" />
        </geometry>
      </collision>
      <collision>
        <origin
          xyz="0.0068359375 -0.00034356117 -0.043485284999999985" />
        <geometry>
          <sphere radius="0.09662318" />
        </geometry>
      </collision>
      <collision>
        <origin
          rpy="0.0 0.0 -${PI_2}"
          xyz="0.008 -0.248 0.0" />
        <geometry>
          <box size="0.34570312 0.18107724 0.3125" />
        </geometry>
      </collision> -->
  </link>
  <link name="head_link1">
    <inertial>
      <origin rpy="0.0 0.0 0.0" xyz="0.0446068140025754 0.00241753143645124 0.0528373754603559"/>
      <mass value="0.414342871921048"/>
      <inertia ixx="0.000158695728344024" ixy="-1.04590928109554e-06" ixz="-6.58530903139189e-06" iyy="0.000117742864399469" iyz="-2.65011299996072e-06" izz="0.000170947040827065"/>
    </inertial>
    <visual>
      <geometry>
        <mesh filename="package://genie_robot_description/meshes/G1/head_link1.fbx"/>
      </geometry>
      <origin rpy="0.0 0.0 0.0" xyz="0.0 0.0 0.0"/>
    </visual>
  </link>
  <link name="head_link2">
    <inertial>
      <origin rpy="0.0 0.0 0.0" xyz="0.0257009265816389 0.0316254080188787 -3.77390122592164e-05"/>
      <mass value="0.707063977171202"/>
      <inertia ixx="0.00205409595373573" ixy="0.000347730118005016" ixz="-2.13857752451204e-06" iyy="0.00200357281313449" iyz="5.16150600423908e-08" izz="0.00184999028444405"/>
    </inertial>
    <visual>
      <geometry>
        <mesh filename="package://genie_robot_description/meshes/G1/head_link2.fbx"/>
      </geometry>
      <origin rpy="-3.141592653589793 0.0 0.0" xyz="0.0 0.0 0.0"/>
    </visual>
    <!-- <collision>
        <geometry>
          <sphere radius="0.11257068650657154" />
        </geometry>
        <origin
          xyz="0.011500973396434619 -0.0252600143348118 0.0008537154007319386"
          rpy="0.0 0.0 0.0" />
      </collision> -->
  </link>
  <link name="arm_base_link"/>
  <link name="arm_l_base_link">
    <inertial>
      <origin rpy="0.0 0.0 0.0" xyz="-0.00020641 0.00057488 0.032296"/>
      <mass value="0.37595"/>
      <inertia ixx="0.00024335" ixy="1.2188e-06" ixz="-2.4281e-06" iyy="0.00024039" iyz="6.6932e-06" izz="0.00032195"/>
    </inertial>
    <visual>
      <geometry>
        <mesh filename="package://genie_robot_description/meshes/G1/arm_l_base_link.fbx"/>
      </geometry>
      <origin rpy="0.0 0.0 0.0" xyz="0.0 0.0 0.0"/>
    </visual>
    <!-- <collision>
        <geometry>
          <cylinder radius="0.05426921699310094" length="0.09134995751082897" />
        </geometry>
        <origin
          xyz="-0.0017106435846521925 0.0013720927967423996 0.02822502050548792"
          rpy="0.0 0.0 0.0" />
      </collision> -->
  </link>
  <link name="arm_r_base_link">
    <inertial>
      <origin rpy="0.0 0.0 0.0" xyz="0.00020641 -0.00057488 0.034396"/>
      <mass value="0.37595"/>
      <inertia ixx="0.00024335" ixy="1.2188e-06" ixz="2.4281e-06" iyy="0.00024039" iyz="-6.6932e-06" izz="0.00032195"/>
    </inertial>
    <visual>
      <geometry>
        <mesh filename="package://genie_robot_description/meshes/G1/arm_r_base_link.fbx"/>
      </geometry>
      <origin rpy="0.0 0.0 0.0" xyz="0.0 0.0 0.0"/>
    </visual>
    <!-- <collision>
        <geometry>
          <cylinder radius="0.05447215073540005" length="0.0913499565795064" />
        </geometry>
        <origin
          xyz="0.001163549527588341 -0.0020492302944608923 0.030325019266456366"
          rpy="0.0 0.0 0.0" />
      </collision> -->
  </link>
  <!-- joints waist -->
  <joint name="idx01_body_joint1" type="prismatic">
    <parent link="base_link"/>
    <child link="body_link1"/>
    <origin rpy="0.0 0.0 0.0" xyz="0.0 0.0 0.6485"/>
    <axis xyz="0.0 0.0 1.0"/>
    <limit effort="100.0" lower="0.0" upper="0.55" velocity="0.1"/>
  </joint>
  <joint name="idx02_body_joint2" type="revolute">
    <parent link="body_link1"/>
    <child link="body_link2"/>
    <origin rpy="-1.5707963267948966 0.0 0.0" xyz="0.131 0.0 0.0"/>
    <axis xyz="0.0 0.0 1.0"/>
    <limit effort="100.0" lower="0.0" upper="1.5707963267948966" velocity="0.5"/>
  </joint>
  <!-- joints head -->
  <joint name="idx11_head_joint1" type="revolute">
    <parent link="body_link2"/>
    <child link="head_link1"/>
    <origin rpy="1.5707963267948966 0.0 0.0" xyz="0.0 -0.441 0.0"/>
    <axis xyz="0.0 0.0 1.0"/>
    <limit effort="50.0" lower="-1.5707963267948966" upper="1.5707963267948966" velocity="1.0"/>
  </joint>
  <joint name="idx12_head_joint2" type="revolute">
    <parent link="head_link1"/>
    <child link="head_link2"/>
    <origin rpy="-1.5707963267948966 0.0 0.0" xyz="0.050238 0.0 0.060065"/>
    <axis xyz="0.0 0.0 1.0"/>
    <limit effort="50.0" lower="-0.3490658503988659" upper="0.5235987755982988" velocity="1.0"/>
  </joint>
  <!-- joints arm base -->
  <joint name="idx10_arm_base_joint" type="fixed">
    <parent link="body_link2"/>
    <child link="arm_base_link"/>
    <origin rpy="1.5707963267948966 0.0 0.0" xyz="0.0 -0.305 0.0"/>
    <axis xyz="0.0 0.0 1.0"/>
  </joint>
  <joint name="idx11_arm_l_base_joint" type="fixed">
    <parent link="arm_base_link"/>
    <child link="arm_l_base_link"/>
    <origin rpy="-1.5707963267948966 0.0 0.0" xyz="0.0 0.025 0.0"/>
    <axis xyz="1.0 0.0 0.0"/>
  </joint>
  <joint name="idx12_arm_r_base_joint" type="fixed">
    <parent link="arm_base_link"/>
    <child link="arm_r_base_link"/>
    <origin rpy="-1.5707963267948966 0.0 3.141592653589793" xyz="0.0 -0.025 0.0"/>
    <axis xyz="1.0 0.0 0.0"/>
  </joint>
  <!-- properties -->
  <!-- links -->
  <link name="arm_l_link1">
    <inertial>
      <origin rpy="0 0 0" xyz="-0.0012655 -0.00043778 -0.018388"/>
      <mass value="0.4936"/>
      <inertia ixx="0.00075396" ixy="6.6935e-06" ixz="6.1141e-06" iyy="0.00065755" iyz="1.2196e-06" izz="0.00031848"/>
    </inertial>
    <visual>
      <origin rpy="0 0 0" xyz="0 0 0"/>
      <geometry>
        <mesh filename="package://genie_robot_description/meshes/G1/arm_l_link1.fbx"/>
      </geometry>
      <material name="white"/>
    </visual>
    <collision>
      <geometry>
        <cylinder length="0.16642063483595848" radius="0.05579268228774888"/>
      </geometry>
      <origin rpy="0.0 0.0 -1.2566370614359172" xyz="0.0026814433577366636 0.0006133775157398935 -0.04071124829351902"/>
    </collision>
  </link>
  <link name="arm_l_link2">
    <inertial>
      <origin rpy="0 0 0" xyz="5.3037e-05 -0.078258 0.0047084"/>
      <mass value="0.46245"/>
      <inertia ixx="0.00065719" ixy="3.7112e-07" ixz="-3.6668e-06" iyy="0.00043459" iyz="-2.517e-05" izz="0.00072571"/>
    </inertial>
    <visual>
      <origin rpy="0 0 0" xyz="0 0 0"/>
      <geometry>
        <mesh filename="package://genie_robot_description/meshes/G1/arm_l_link2.fbx"/>
      </geometry>
      <material name="white"/>
    </visual>
    <collision>
      <origin rpy="1.5707963267948966 0 0" xyz="0.0 -0.044062052 0.0009765625"/>
      <geometry>
        <cylinder length="0.18085919" radius="0.06302423"/>
      </geometry>
    </collision>
  </link>
  <link name="arm_l_link3">
    <inertial>
      <origin rpy="0 0 0" xyz="-0.0012032 0.0008714 -0.055265"/>
      <mass value="0.50026"/>
      <inertia ixx="0.0013016" ixy="3.1401e-06" ixz="1.4255e-05" iyy="0.001427" iyz="2.4361e-05" izz="0.00033587"/>
    </inertial>
    <visual>
      <origin rpy="0 0 0" xyz="0 0 0"/>
      <geometry>
        <mesh filename="package://genie_robot_description/meshes/G1/arm_l_link3.fbx"/>
      </geometry>
      <material name="white"/>
    </visual>
    <collision>
      <origin rpy="3.141592653589793 -1.2246467991473532e-16 2.5132741228718345" xyz="-0.002745052027917949 0.000636008250640886 -0.07223940640687943"/>
      <geometry>
        <cylinder length="0.22069887816905975" radius="0.05423258091998755"/>
      </geometry>
    </collision>
  </link>
  <link name="arm_l_link4">
    <inertial>
      <origin rpy="0 0 0" xyz="3.7035e-05 -0.06248 0.0025377"/>
      <mass value="0.27473"/>
      <inertia ixx="0.00029284" ixy="4.6615e-07" ixz="6.2359e-08" iyy="0.00018853" iyz="-1.1062e-06" izz="0.00031238"/>
    </inertial>
    <visual>
      <origin rpy="0 0 0" xyz="0 0 0"/>
      <geometry>
        <mesh filename="package://genie_robot_description/meshes/G1/arm_l_link4.fbx"/>
      </geometry>
      <material name="white"/>
    </visual>
    <collision>
      <origin rpy="1.5707963267948966 0 0" xyz="0.0 -0.03817895 -0.0043945312"/>
      <geometry>
        <cylinder length="0.154955404" radius="0.057891708"/>
      </geometry>
    </collision>
  </link>
  <link name="arm_l_link5">
    <inertial>
      <origin rpy="0 0 0" xyz="-7.9404e-07 -0.00023094 -0.024143"/>
      <mass value="0.25139"/>
      <inertia ixx="0.00023516" ixy="-1.3496e-09" ixz="-2.0314e-08" iyy="0.00028808" iyz="-1.2106e-05" izz="0.00013069"/>
    </inertial>
    <visual>
      <origin rpy="0 0 0" xyz="0 0 0"/>
      <geometry>
        <mesh filename="package://genie_robot_description/meshes/G1/arm_l_link5.fbx"/>
      </geometry>
      <material name="white"/>
    </visual>
    <collision>
      <origin rpy="0.0 0.0 -0.6283185307179586" xyz="0.00013161953185003987 -5.835551655943335e-05 -0.033305803313851357"/>
      <geometry>
        <cylinder length="0.13452399894595146" radius="0.045614576801007695"/>
      </geometry>
    </collision>
  </link>
  <link name="arm_l_link6">
    <inertial>
      <origin rpy="0 0 0" xyz="1.769e-06 -0.086692 0.0025571"/>
      <mass value="0.26634"/>
      <inertia ixx="0.00031434" ixy="-2.9254e-09" ixz="1.0017e-07" iyy="0.00014464" iyz="-2.0329e-05" izz="0.0003245"/>
    </inertial>
    <visual>
      <origin rpy="0 0 0" xyz="0 0 0"/>
      <geometry>
        <mesh filename="package://genie_robot_description/meshes/G1/arm_l_link6.fbx"/>
      </geometry>
      <material name="white"/>
    </visual>
    <collision>
      <origin rpy="-5.990089690983079e-19 -1.4805425285141327 -1.5677635369963552" xyz="0.0002549462426528953 -0.055477687883556816 -0.0019394332157672595"/>
      <geometry>
        <cylinder length="0.1816599826988493" radius="0.048507387167967514"/>
      </geometry>
    </collision>
  </link>
  <link name="arm_l_end_link">
    <inertial>
      <origin rpy="0 0 0" xyz="-7.5113e-05 -0.00024521 -0.016705"/>
      <mass value="0.06158"/>
      <inertia ixx="1.8407e-05" ixy="3.4796e-08" ixz="-3.2424e-09" iyy="1.818e-05" iyz="1.1327e-07" izz="2.8547e-05"/>
    </inertial>
    <visual>
      <origin rpy="0 0 0" xyz="0 0 0"/>
      <geometry>
        <mesh filename="package://genie_robot_description/meshes/G1/arm_l_link7.fbx"/>
      </geometry>
      <material name="white"/>
    </visual>
    <collision>
      <origin rpy="3.141592653589793 -1.2246467991473532e-16 3.141592653589793" xyz="-4.552953707661759e-05 -0.002300474691790042 -0.02249999972991645"/>
      <geometry>
        <cylinder length="0.045999998692423105" radius="0.030799950382754494"/>
      </geometry>
    </collision>
  </link>
  <link name="hand_l_center_link">
    </link>
  <joint name="idx52_gripper_l_center_joint" type="fixed">
    <origin rpy="0 0 -1.5707963267948966" xyz="0.03 0.065 0.11669"/>
    <parent link="hand_l_base_link"/>
    <child link="hand_l_center_link"/>
  </joint>
  <link name="hand_r_center_link">
    </link>
  <joint name="idx92_gripper_r_center_joint" type="fixed">
    <origin rpy="0 0 -1.5707963267948966" xyz="-0.03 0.065 0.11491"/>
    <parent link="hand_r_base_link"/>
    <child link="hand_r_center_link"/>
  </joint>
  <!-- joints -->
  <joint name="idx21_arm_l_joint1" type="revolute">
    <parent link="arm_l_base_link"/>
    <child link="arm_l_link1"/>
    <origin rpy="0 0 0" xyz="0.0 0.0 0.1859"/>
    <axis xyz="0.0 0.0 1.0"/>
    <limit effort="60.0" lower="-3.14" upper="3.14" velocity="3.14"/>
  </joint>
  <joint name="idx22_arm_l_joint2" type="revolute">
    <parent link="arm_l_link1"/>
    <child link="arm_l_link2"/>
    <origin rpy="-1.5707963267948966 0.0 1.5707963267948966" xyz="0.0 0.0 0.0"/>
    <axis xyz="0.0 0.0 1.0"/>
    <limit effort="60.0" lower="-2.09" upper="1.48" velocity="3.14"/>
  </joint>
  <joint name="idx23_arm_l_joint3" type="revolute">
    <parent link="arm_l_link2"/>
    <child link="arm_l_link3"/>
    <origin rpy="-1.5707963267948966 1.5707963267948966 3.141592653589793" xyz="0.0 -0.305 0.0"/>
    <axis xyz="0.0 0.0 1.0"/>
    <limit effort="60.0" lower="-3.10" upper="3.10" velocity="3.14"/>
  </joint>
  <joint name="idx24_arm_l_joint4" type="revolute">
    <parent link="arm_l_link3"/>
    <child link="arm_l_link4"/>
    <origin rpy="-1.5707963267948966 0.0 3.141592653589793" xyz="0.0 0.0 0.0"/>
    <axis xyz="0.0 0.0 1.0"/>
    <limit effort="60.0" lower="-1.48" upper="1.48" velocity="3.14"/>
  </joint>
  <joint name="idx25_arm_l_joint5" type="revolute">
    <parent link="arm_l_link4"/>
    <child link="arm_l_link5"/>
    <origin rpy="-1.5707963267948966 0.0 -3.141592653589793" xyz="0.0 -0.1975 0.0"/>
    <axis xyz="0.0 0.0 1.0"/>
    <limit effort="30.0" lower="-3.10" upper="3.10" velocity="3.14"/>
  </joint>
  <joint name="idx26_arm_l_joint6" type="revolute">
    <parent link="arm_l_link5"/>
    <child link="arm_l_link6"/>
    <origin rpy="-1.5707963267948966 0.0 0.0" xyz="0.0 0.0 0.0"/>
    <axis xyz="0.0 0.0 1.0"/>
    <limit effort="30.0" lower="-1.74" upper="1.74" velocity="3.14"/>
  </joint>
  <joint name="idx27_arm_l_joint7" type="revolute">
    <origin rpy="1.5707963267948966 0.0 0.0" xyz="0.0 -0.1805 0.0"/>
    <parent link="arm_l_link6"/>
    <child link="arm_l_end_link"/>
    <axis xyz="0.0 0.0 1.0"/>
    <limit effort="30.0" lower="-3.10" upper="3.10" velocity="3.14"/>
  </joint>
  <!-- properties -->
  <!-- links -->
  <link name="arm_r_link1">
    <inertial>
      <origin rpy="0 0 0" xyz="0.0012679 -0.0001581 -0.018109"/>
      <mass value="0.4936"/>
      <inertia ixx="0.00075396" ixy="-2.4144e-06" ixz="-1.8364e-06" iyy="0.0006605" iyz="1.2174e-06" izz="0.00031553"/>
    </inertial>
    <visual>
      <origin rpy="0 0 0" xyz="0 0 0"/>
      <geometry>
        <mesh filename="package://genie_robot_description/meshes/G1/arm_r_link1.fbx"/>
      </geometry>
      <material name="white"/>
    </visual>
    <collision>
      <origin rpy="-3.141592653589793 -1.2246467991473535e-16 1.2566370614359175" xyz="0.00018724019569230644 -0.002004870648449318 -0.04071185737848282"/>
      <geometry>
        <cylinder length="0.16642716526985168" radius="0.0548390473201415"/>
      </geometry>
    </collision>
  </link>
  <link name="arm_r_link2">
    <inertial>
      <origin rpy="0 0 0" xyz="-0.00044207 -0.082298 0.00019486"/>
      <mass value="0.41662"/>
      <inertia ixx="0.00054592" ixy="4.7265e-06" ixz="2.4946e-06" iyy="0.00039507" iyz="-2.0629e-05" izz="0.00057791"/>
    </inertial>
    <visual>
      <origin rpy="0 0 0" xyz="0 0 0"/>
      <geometry>
        <mesh filename="package://genie_robot_description/meshes/G1/arm_r_link2.fbx"/>
      </geometry>
      <material name="white"/>
    </visual>
    <collision>
      <origin rpy="1.5707963267948966 0 0" xyz="0.0 -0.044062052 0.0009765625"/>
      <geometry>
        <cylinder length="0.18085919" radius="0.06302423"/>
      </geometry>
    </collision>
  </link>
  <link name="arm_r_link3">
    <inertial>
      <origin rpy="0 0 0" xyz="0.0010558 4.4416e-05 -0.056128"/>
      <mass value="0.49413"/>
      <inertia ixx="0.0013405" ixy="-6.8527e-07" ixz="-1.3381e-05" iyy="0.00142" iyz="2.8511e-05" izz="0.00037605"/>
    </inertial>
    <visual>
      <origin rpy="0 0 0" xyz="0 0 0"/>
      <geometry>
        <mesh filename="package://genie_robot_description/meshes/G1/arm_r_link3.fbx"/>
      </geometry>
      <material name="white"/>
    </visual>
    <collision>
      <origin rpy="0 0 0" xyz="0.0006559932284637068 -2.2628975236450855e-05 -0.07219303026795387"/>
      <geometry>
        <cylinder length="0.22061403840780258" radius="0.05216156143823925"/>
      </geometry>
    </collision>
  </link>
  <link name="arm_r_link4">
    <inertial>
      <origin rpy="0 0 0" xyz="2.4212e-05 -0.06248 0.002536"/>
      <mass value="0.27473"/>
      <inertia ixx="0.00029283" ixy="4.5586e-07" ixz="5.8042e-08" iyy="0.00018852" iyz="-1.116e-06" izz="0.00031238"/>
    </inertial>
    <visual>
      <origin rpy="0 0 0" xyz="0 0 0"/>
      <geometry>
        <mesh filename="package://genie_robot_description/meshes/G1/arm_r_link4.fbx"/>
      </geometry>
      <material name="white"/>
    </visual>
    <collision>
      <origin rpy="1.5707963267948966 0 0" xyz="0.0 -0.03817895 -0.0043945312"/>
      <geometry>
        <cylinder length="0.154955404" radius="0.057891708"/>
      </geometry>
    </collision>
  </link>
  <link name="arm_r_link5">
    <inertial>
      <origin rpy="0 0 0" xyz="2.6223e-06 -0.00023041 -0.024141"/>
      <mass value="0.25139"/>
      <inertia ixx="0.00023516" ixy="-6.5868e-09" ixz="-1.9428e-08" iyy="0.00028807" iyz="-1.2108e-05" izz="0.00013068"/>
    </inertial>
    <visual>
      <origin rpy="0 0 0" xyz="0 0 0"/>
      <geometry>
        <mesh filename="package://genie_robot_description/meshes/G1/arm_r_link5.fbx"/>
      </geometry>
      <material name="white"/>
    </visual>
    <collision>
      <origin rpy="0 0 0" xyz="-0.00022255510134868567 -4.227476414728204e-05 -0.03344946540892124"/>
      <geometry>
        <cylinder length="0.13423806056380272" radius="0.04562028545392604"/>
      </geometry>
    </collision>
  </link>
  <link name="arm_r_link6">
    <inertial>
      <origin rpy="0 0 0" xyz="5.0382e-06 -0.086696 0.002556"/>
      <mass value="0.26634"/>
      <inertia ixx="0.00031434" ixy="-1.2113e-09" ixz="1.0011e-07" iyy="0.00014464" iyz="-2.033e-05" izz="0.00032449"/>
    </inertial>
    <visual>
      <origin rpy="0 0 0" xyz="0 0 0"/>
      <geometry>
        <mesh filename="package://genie_robot_description/meshes/G1/arm_r_link6.fbx"/>
      </geometry>
      <material name="white"/>
    </visual>
    <collision>
      <origin rpy="0.0 -1.4835107730827122 -1.56897465223053" xyz="-1.7782549414354032e-05 -0.05507596972928094 -0.0017447156928267265"/>
      <geometry>
        <cylinder length="0.18272488500982115" radius="0.04857149291994264"/>
      </geometry>
    </collision>
  </link>
  <link name="arm_r_end_link">
    <inertial>
      <origin rpy="0 0 0" xyz="-7.5134e-05 -0.00024521 -0.016705"/>
      <mass value="0.06158"/>
      <inertia ixx="1.8407e-05" ixy="3.4818e-08" ixz="-3.2902e-09" iyy="1.818e-05" iyz="1.1326e-07" izz="2.8547e-05"/>
    </inertial>
    <visual>
      <origin rpy="0 0 0" xyz="0 0 0"/>
      <geometry>
        <mesh filename="package://genie_robot_description/meshes/G1/arm_r_link7.fbx"/>
      </geometry>
      <material name="white"/>
    </visual>
    <collision>
      <origin rpy="3.141592653589793 -1.2246467991473532e-16 3.141592653589793" xyz="-4.552953707661759e-05 -0.002300474691790042 -0.02249999972991645"/>
      <geometry>
        <cylinder length="0.045999998692423105" radius="0.030799950382754494"/>
      </geometry>
    </collision>
  </link>
  <!-- joints -->
  <joint name="idx61_arm_r_joint1" type="revolute">
    <parent link="arm_r_base_link"/>
    <child link="arm_r_link1"/>
    <origin rpy="0 0 0" xyz="0.0 0.0 0.188"/>
    <axis xyz="0.0 0.0 1.0"/>
    <limit effort="60.0" lower="-3.14" upper="3.14" velocity="3.14"/>
  </joint>
  <joint name="idx62_arm_r_joint2" type="revolute">
    <parent link="arm_r_link1"/>
    <child link="arm_r_link2"/>
    <origin rpy="-1.5707963267948966 0.0 -1.5707963267948966" xyz="0.0 0.0 0.0"/>
    <axis xyz="0.0 0.0 1.0"/>
    <limit effort="60.0" lower="-1.48" upper="2.09" velocity="3.14"/>
  </joint>
  <joint name="idx63_arm_r_joint3" type="revolute">
    <parent link="arm_r_link2"/>
    <child link="arm_r_link3"/>
    <origin rpy="-1.5707963267948966 -1.5707963267948966 3.141592653589793" xyz="0.0 -0.305 0.0"/>
    <axis xyz="0.0 0.0 1.0"/>
    <limit effort="60.0" lower="-3.10" upper="3.10" velocity="3.14"/>
  </joint>
  <joint name="idx64_arm_r_joint4" type="revolute">
    <parent link="arm_r_link3"/>
    <child link="arm_r_link4"/>
    <origin rpy="-1.5707963267948966 0.0 3.141592653589793" xyz="0.0 0.0 0.0"/>
    <axis xyz="0.0 0.0 1.0"/>
    <limit effort="60.0" lower="-1.48" upper="1.48" velocity="3.14"/>
  </joint>
  <joint name="idx65_arm_r_joint5" type="revolute">
    <parent link="arm_r_link4"/>
    <child link="arm_r_link5"/>
    <origin rpy="-1.5707963267948966 0.0 -3.141592653589793" xyz="0.0 -0.1975 0.0"/>
    <axis xyz="0.0 0.0 1.0"/>
    <limit effort="30.0" lower="-3.10" upper="3.10" velocity="3.14"/>
  </joint>
  <joint name="idx66_arm_r_joint6" type="revolute">
    <parent link="arm_r_link5"/>
    <child link="arm_r_link6"/>
    <origin rpy="-1.5707963267948966 0.0 0.0" xyz="0.0 0.0 0.0"/>
    <axis xyz="0.0 0.0 1.0"/>
    <limit effort="30.0" lower="-1.74" upper="1.74" velocity="3.14"/>
  </joint>
  <joint name="idx67_arm_r_joint7" type="revolute">
    <origin rpy="1.5707963267948966 0.0 0.0" xyz="0.0 -0.1805 0.0"/>
    <parent link="arm_r_link6"/>
    <child link="arm_r_end_link"/>
    <axis xyz="0.0 0.0 1.0"/>
    <limit effort="30.0" lower="-3.10" upper="3.10" velocity="3.14"/>
  </joint>
  <joint name="idx51_ee_l_joint" type="fixed">
    <parent link="arm_l_end_link"/>
    <child link="hand_l_base_link"/>
    <origin rpy="0 0 0" xyz="0 0 0"/>
    <axis xyz="0.0 0.0 0.0"/>
  </joint>
  <link name="hand_l_base_link">
    <inertial>
      <origin rpy="0 0 0" xyz="0.000669391831861252 0.000519695443695789 0.0491475460895892"/>
      <mass value="0.34872"/>
      <inertia ixx="8.5056866062116E-05" ixy="2.5563300532887E-07" ixz="6.76775419174209E-07" iyy="0.000128963143156167" iyz="-2.47204557657288E-06" izz="6.68762609717364E-05"/>
    </inertial>
    <visual>
      <origin rpy="0 0 0" xyz="0 0 0"/>
      <geometry>
        <mesh filename="package://genie_robot_description/meshes/skillhands6/L_base_link.STL" scale="-1 1 1"/>
      </geometry>
      <material name="">
        <color rgba="0.792156862745098 0.819607843137255 0.933333333333333 1"/>
      </material>
    </visual>
    <collision>
      <origin rpy="0 0 0" xyz="0 0 0"/>
      <geometry>
        <mesh filename="package://genie_robot_description/meshes/skillhands6/L_base_link.STL"/>
      </geometry>
    </collision>
  </link>
  <link name="hand_l_thumb_link0">
    <inertial>
      <origin rpy="0 0 0" xyz="0.00794384103660506 0.000525099392806788 0.00697350249829382"/>
      <mass value="0.00293"/>
      <inertia ixx="9.46674037152461E-08" ixy="-2.82873244389597E-09" ixz="-6.48785031840717E-10" iyy="1.37273390833953E-07" iyz="-4.27730445158918E-11" izz="9.49139790727193E-08"/>
    </inertial>
    <visual>
      <origin rpy="0 0 0" xyz="0 0 0"/>
      <geometry>
        <mesh filename="package://genie_robot_description/meshes/skillhands6/L_thumb_swing.STL"/>
      </geometry>
      <material name="">
        <color rgba="0.792156862745098 0.819607843137255 0.933333333333333 1"/>
      </material>
    </visual>
    <collision>
      <origin rpy="0 0 0" xyz="0 0 0"/>
      <geometry>
        <mesh filename="package://genie_robot_description/meshes/skillhands6/L_thumb_swing.STL"/>
      </geometry>
    </collision>
  </link>
  <joint name="hand_l_thumb_joint0" type="revolute">
    <origin rpy="0 0 0" xyz="0.028697 0.021402 0.020004"/>
    <parent link="hand_l_base_link"/>
    <child link="hand_l_thumb_link0"/>
    <axis xyz="0 0 1"/>
    <limit effort="10" lower="0" upper="2.286" velocity="1"/>
  </joint>
  <link name="hand_l_thumb_link1">
    <inertial>
      <origin rpy="0 0 0" xyz="-0.0241014201585216 0.0111736357363578 0.00502576384433179"/>
      <mass value="0.04967"/>
      <inertia ixx="2.93305966994507E-06" ixy="9.76969594917475E-07" ixz="8.08967323966058E-10" iyy="3.02939717110803E-06" iyz="-1.91040333397148E-09" izz="5.22017243205931E-06"/>
    </inertial>
    <visual>
      <origin rpy="0 0 0" xyz="0 0 0"/>
      <geometry>
        <mesh filename="package://genie_robot_description/meshes/skillhands6/L_thumb_1.STL"/>
      </geometry>
      <material name="">
        <color rgba="0.792156862745098 0.819607843137255 0.933333333333333 1"/>
      </material>
    </visual>
    <collision>
      <origin rpy="0 0 0" xyz="0 0 0"/>
      <geometry>
        <mesh filename="package://genie_robot_description/meshes/skillhands6/L_thumb_1.STL"/>
      </geometry>
    </collision>
  </link>
  <joint name="hand_l_thumb_joint1" type="revolute">
    <origin rpy="1.5708 0 -3.0756" xyz="0.0137 -0.0041554 0.0057468"/>
    <parent link="hand_l_thumb_link0"/>
    <child link="hand_l_thumb_link1"/>
    <axis xyz="0 0 -1"/>
    <limit effort="10" lower="0" upper="0.4765" velocity="1"/>
  </joint>
  <link name="hand_l_thumb_link2">
    <inertial>
      <origin rpy="0 0 0" xyz="-0.0112963677317678 0.00190116548089214 -0.00768961336616791"/>
      <mass value="0.00955"/>
      <inertia ixx="4.33823690884257E-07" ixy="3.01954259870628E-08" ixz="6.11449732674661E-11" iyy="3.41580236349291E-07" iyz="-1.1408901535091E-10" izz="4.77758554245155E-07"/>
    </inertial>
    <visual>
      <origin rpy="0 0 0" xyz="0 0 0"/>
      <geometry>
        <mesh filename="package://genie_robot_description/meshes/skillhands6/L_thumb_2.STL"/>
      </geometry>
      <material name="">
        <color rgba="0.792156862745098 0.819607843137255 0.933333333333333 1"/>
      </material>
    </visual>
    <collision>
      <origin rpy="0 0 0" xyz="0 0 0"/>
      <geometry>
        <mesh filename="package://genie_robot_description/meshes/skillhands6/L_thumb_2.STL"/>
      </geometry>
    </collision>
  </link>
  <joint name="hand_l_thumb_joint2" type="revolute">
    <origin rpy="0 0 0" xyz="-0.038942 0.037904 0.01275"/>
    <parent link="hand_l_thumb_link1"/>
    <child link="hand_l_thumb_link2"/>
    <axis xyz="0 0 -1"/>
    <limit effort="10" lower="0" upper="0.888" velocity="1.822"/>
    <!--<mimic joint="hand_l_thumb_joint1" multiplier="1.822" offset="0"/>-->
  </joint>
  <link name="hand_l_thumb_link3">
    <inertial>
      <origin rpy="0 0 0" xyz="-0.00856543035521623 0.00586043918899951 -0.00530178580590995"/>
      <mass value="0.01039"/>
      <inertia ixx="4.15484662408592E-07" ixy="1.25273342106128E-07" ixz="-1.11870657410123E-10" iyy="2.49667763205503E-07" iyz="1.83163778457604E-10" izz="4.96196089308723E-07"/>
    </inertial>
    <visual>
      <origin rpy="0 0 0" xyz="0 0 0"/>
      <geometry>
        <mesh filename="package://genie_robot_description/meshes/skillhands6/L_thumb_3.STL"/>
      </geometry>
      <material name="">
        <color rgba="0.792156862745098 0.819607843137255 0.933333333333333 1"/>
      </material>
    </visual>
    <collision>
      <origin rpy="0 0 0" xyz="0 0 0"/>
      <geometry>
        <mesh filename="package://genie_robot_description/meshes/skillhands6/L_thumb_3.STL"/>
      </geometry>
    </collision>
  </link>
  <joint name="hand_l_thumb_joint3" type="revolute">
    <origin rpy="0 0 0" xyz="-0.01728 0.014743 -0.0024"/>
    <parent link="hand_l_thumb_link2"/>
    <child link="hand_l_thumb_link3"/>
    <axis xyz="0 0 -1"/>
    <limit effort="10" lower="0" upper="0.705" velocity="1.3769"/>
    <!--<mimic joint="hand_l_thumb_joint2" multiplier="0.7557" offset="0"/>-->
  </joint>
  <link name="hand_l_index_link1">
    <inertial>
      <origin rpy="0 0 0" xyz="-0.00224102799550208 0.0120773787288955 -0.00604980652633819"/>
      <mass value="0.01247"/>
      <inertia ixx="6.70830928527695E-07" ixy="6.24703692121794E-09" ixz="2.13307894311699E-12" iyy="2.67072428610071E-07" iyz="-9.08936981939241E-12" izz="6.64558171930923E-07"/>
    </inertial>
    <visual>
      <origin rpy="0 0 0" xyz="0 0 0"/>
      <geometry>
        <mesh filename="package://genie_robot_description/meshes/skillhands6/L_index_1.STL"/>
      </geometry>
      <material name="">
        <color rgba="0.792156862745098 0.819607843137255 0.933333333333333 1"/>
      </material>
    </visual>
    <collision>
      <origin rpy="0 0 0" xyz="0 0 0"/>
      <geometry>
        <mesh filename="package://genie_robot_description/meshes/skillhands6/L_index_1.STL"/>
      </geometry>
    </collision>
  </link>
  <joint name="hand_l_index_joint1" type="revolute">
    <origin rpy="1.6319 0.04887 1.5708" xyz="0.034163 0.00015626 0.10177"/>
    <parent link="hand_l_base_link"/>
    <child link="hand_l_index_link1"/>
    <axis xyz="0 0 -1"/>
    <limit effort="10" lower="0" upper="1.566" velocity="1"/>
  </joint>
  <link name="hand_l_index_link2">
    <inertial>
      <origin rpy="0 0 0" xyz="-0.00267181281126358 0.0187446193774337 -0.00505000944787351"/>
      <mass value="0.00996"/>
      <inertia ixx="8.55152683615466E-07" ixy="-8.71734151829103E-08" ixz="-6.50777100689624E-14" iyy="1.37438503678449E-07" iyz="1.75332406275978E-12" izz="8.7134409310854E-07"/>
    </inertial>
    <visual>
      <origin rpy="0 0 0" xyz="0 0 0"/>
      <geometry>
        <mesh filename="package://genie_robot_description/meshes/skillhands6/L_index_2.STL"/>
      </geometry>
      <material name="">
        <color rgba="0.792156862745098 0.819607843137255 0.933333333333333 1"/>
      </material>
    </visual>
    <collision>
      <origin rpy="0 0 0" xyz="0 0 0"/>
      <geometry>
        <mesh filename="package://genie_robot_description/meshes/skillhands6/L_index_2.STL"/>
      </geometry>
    </collision>
  </link>
  <joint name="hand_l_index_joint2" type="revolute">
    <origin rpy="0 0 -0.03665" xyz="0.000257313406975795 0.0321313914926673 -0.000999999999997433"/>
    <parent link="hand_l_index_link1"/>
    <child link="hand_l_index_link2"/>
    <axis xyz="0 0 -1"/>
    <limit effort="10" lower="0" upper="1.753" velocity="1.0901"/>
    <!--<mimic joint="hand_l_index_joint1" multiplier="1.0901" offset="0"/>-->
  </joint>
  <link name="hand_l_middle_link1">
    <inertial>
      <origin rpy="0 0 0" xyz="-0.00224098733007597 0.0120772897382423 -0.00604988790740668"/>
      <mass value="0.01247"/>
      <inertia ixx="6.7082918655762E-07" ixy="6.24726967642179E-09" ixz="1.71410357783072E-12" iyy="2.67074190271052E-07" iyz="-7.88392050737899E-12" izz="6.64557797065168E-07"/>
    </inertial>
    <visual>
      <origin rpy="0 0 0" xyz="0 0 0"/>
      <geometry>
        <mesh filename="package://genie_robot_description/meshes/skillhands6/L_middle_1.STL"/>
      </geometry>
      <material name="">
        <color rgba="0.792156862745098 0.819607843137255 0.933333333333333 1"/>
      </material>
    </visual>
    <collision>
      <origin rpy="0 0 0" xyz="0 0 0"/>
      <geometry>
        <mesh filename="package://genie_robot_description/meshes/skillhands6/L_middle_1.STL"/>
      </geometry>
    </collision>
  </link>
  <joint name="hand_l_middle_joint1" type="revolute">
    <origin rpy="1.5708 0.04887 1.5708" xyz="0.014247 0.00015626 0.1026"/>
    <parent link="hand_l_base_link"/>
    <child link="hand_l_middle_link1"/>
    <axis xyz="0 0 -1"/>
    <limit effort="10" lower="0" upper="1.566" velocity="1"/>
  </joint>
  <link name="hand_l_middle_link2">
    <inertial>
      <origin rpy="0 0 0" xyz="-0.00246986089083429 0.024324149758177 -0.00505001482330504"/>
      <mass value="0.01048"/>
      <inertia ixx="1.39047581953365E-06" ixy="-8.94538746050567E-08" ixz="3.61053610049558E-13" iyy="2.11811380763581E-07" iyz="7.8205550672438E-12" izz="1.4019704232162E-06"/>
    </inertial>
    <visual>
      <origin rpy="0 0 0" xyz="0 0 0"/>
      <geometry>
        <mesh filename="package://genie_robot_description/meshes/skillhands6/L_middle_2.STL"/>
      </geometry>
      <material name="">
        <color rgba="0.792156862745098 0.819607843137255 0.933333333333333 1"/>
      </material>
    </visual>
    <collision>
      <origin rpy="0 0 0" xyz="0 0 0"/>
      <geometry>
        <mesh filename="package://genie_robot_description/meshes/skillhands6/L_middle_2.STL"/>
      </geometry>
    </collision>
  </link>
  <joint name="hand_l_middle_joint2" type="revolute">
    <origin rpy="0 0 -0.03665" xyz="0.00025731352440872 0.0321313914917269 -0.000999999999997447"/>
    <parent link="hand_l_middle_link1"/>
    <child link="hand_l_middle_link2"/>
    <axis xyz="0 0 -1"/>
    <limit effort="10" lower="0" upper="1.753" velocity="1.0901"/>
    <!--<mimic joint="hand_l_middle_joint1" multiplier="1.0901" offset="0"/>-->
  </joint>
  <link name="hand_l_ring_link1">
    <inertial>
      <origin rpy="0 0 0" xyz="-0.0022409845097742 0.0120772660237512 -0.0060498790574241"/>
      <mass value="0.01247"/>
      <inertia ixx="6.70828070846502E-07" ixy="6.24721192893163E-09" ixz="1.82833188410862E-12" iyy="2.67073887112504E-07" iyz="-8.61419592489313E-12" izz="6.64556475611479E-07"/>
    </inertial>
    <visual>
      <origin rpy="0 0 0" xyz="0 0 0"/>
      <geometry>
        <mesh filename="package://genie_robot_description/meshes/skillhands6/L_ring_1.STL"/>
      </geometry>
      <material name="">
        <color rgba="0.792156862745098 0.819607843137255 0.933333333333333 1"/>
      </material>
    </visual>
    <collision>
      <origin rpy="0 0 0" xyz="0 0 0"/>
      <geometry>
        <mesh filename="package://genie_robot_description/meshes/skillhands6/L_ring_1.STL"/>
      </geometry>
    </collision>
  </link>
  <joint name="hand_l_ring_joint1" type="revolute">
    <origin rpy="1.5184 0.04887 1.5708" xyz="-0.0064906 0.00015626 0.10242"/>
    <parent link="hand_l_base_link"/>
    <child link="hand_l_ring_link1"/>
    <axis xyz="0 0 -1"/>
    <limit effort="10" lower="0" upper="1.566" velocity="1"/>
  </joint>
  <link name="hand_l_ring_link2">
    <inertial>
      <origin rpy="0 0 0" xyz="-0.00246986300836047 0.0243241390396778 -0.00505001933599687"/>
      <mass value="0.01048"/>
      <inertia ixx="1.39047259970293E-06" ixy="-8.94527619908525E-08" ixz="4.88933666294306E-13" iyy="2.11811759833005E-07" iyz="7.21130931926255E-12" izz="1.40196659853308E-06"/>
    </inertial>
    <visual>
      <origin rpy="0 0 0" xyz="0 0 0"/>
      <geometry>
        <mesh filename="package://genie_robot_description/meshes/skillhands6/L_ring_2.STL"/>
      </geometry>
      <material name="">
        <color rgba="0.792156862745098 0.819607843137255 0.933333333333333 1"/>
      </material>
    </visual>
    <collision>
      <origin rpy="0 0 0" xyz="0 0 0"/>
      <geometry>
        <mesh filename="package://genie_robot_description/meshes/skillhands6/L_ring_2.STL"/>
      </geometry>
    </collision>
  </link>
  <joint name="hand_l_ring_joint2" type="revolute">
    <origin rpy="0 0 -0.03665" xyz="0.000257313581064927 0.0321313914912732 -0.000999999999997447"/>
    <parent link="hand_l_ring_link1"/>
    <child link="hand_l_ring_link2"/>
    <axis xyz="0 0 -1"/>
    <limit effort="10" lower="0" upper="1.753" velocity="1.0901"/>
    <!--<mimic joint="hand_l_ring_joint1" multiplier="1.0901" offset="0"/>-->
  </joint>
  <link name="hand_l_little_link1">
    <inertial>
      <origin rpy="0 0 0" xyz="-0.00224103836860429 0.0120773675149673 -0.00604983498739138"/>
      <mass value="0.01247"/>
      <inertia ixx="6.70834624606976E-07" ixy="6.24947596494719E-09" ixz="2.80661570406762E-12" iyy="2.67075426325195E-07" iyz="-1.09546145092332E-11" izz="6.64562921739067E-07"/>
    </inertial>
    <visual>
      <origin rpy="0 0 0" xyz="0 0 0"/>
      <geometry>
        <mesh filename="package://genie_robot_description/meshes/skillhands6/L_little_1.STL"/>
      </geometry>
      <material name="">
        <color rgba="0.792156862745098 0.819607843137255 0.933333333333333 1"/>
      </material>
    </visual>
    <collision>
      <origin rpy="0 0 0" xyz="0 0 0"/>
      <geometry>
        <mesh filename="package://genie_robot_description/meshes/skillhands6/L_little_1.STL"/>
      </geometry>
    </collision>
  </link>
  <joint name="hand_l_little_joint1" type="revolute">
    <origin rpy="1.46607657167534 0.04887 1.57079632679191" xyz="-0.0267358938400573 0.000156259167782641 0.101113988883024"/>
    <parent link="hand_l_base_link"/>
    <child link="hand_l_little_link1"/>
    <axis xyz="0 0 -1"/>
    <limit effort="10" lower="0" upper="1.566" velocity="1"/>
  </joint>
  <link name="hand_l_little_link2">
    <inertial>
      <origin rpy="0 0 0" xyz="-0.00348949322629896 0.0170315075858032 -0.0050500735997519"/>
      <mass value="0.00792"/>
      <inertia ixx="5.09178867517819E-07" ixy="-1.55519766650118E-08" ixz="-1.24872024789945E-12" iyy="1.38789524007397E-07" iyz="-5.031480971821E-12" izz="5.21389602220666E-07"/>
    </inertial>
    <visual>
      <origin rpy="0 0 0" xyz="0 0 0"/>
      <geometry>
        <mesh filename="package://genie_robot_description/meshes/skillhands6/L_little_2.STL"/>
      </geometry>
      <material name="">
        <color rgba="0.792156862745098 0.819607843137255 0.933333333333333 1"/>
      </material>
    </visual>
    <collision>
      <origin rpy="0 0 0" xyz="0 0 0"/>
      <geometry>
        <mesh filename="package://genie_robot_description/meshes/skillhands6/L_little_2.STL"/>
      </geometry>
    </collision>
  </link>
  <joint name="hand_l_little_joint2" type="revolute">
    <origin rpy="0 0 -0.03665" xyz="0.000257313598265113 0.0321313914911354 -0.000999999999997433"/>
    <parent link="hand_l_little_link1"/>
    <child link="hand_l_little_link2"/>
    <axis xyz="0 0 -1"/>
    <limit effort="10" lower="0" upper="1.753" velocity="1.0901"/>
    <!--<mimic joint="hand_l_little_joint1" multiplier="1.0901" offset="0"/>-->
  </joint>
  <gazebo>
    <plugin filename="libgazebo_ros_control.so" name="gazebo_ros_control">
      <robotNamespace>/</robotNamespace>
      <legacyModeNS>true</legacyModeNS>
      <controlPeriod>0.001</controlPeriod>
      <robotSimType>gazebo_ros_control/DefaultRobotHWSim</robotSimType>
    </plugin>
  </gazebo>
  <transmission name="tran1">
    <type>transmission_interface/SimpleTransmission</type>
    <joint name="hand_l_thumb_joint0">
      <hardwareInterface>hardware_interface/PositionJointInterface</hardwareInterface>
    </joint>
    <actuator name="motor1">
      <hardwareInterface>hardware_interface/PositionJointInterface</hardwareInterface>
      <mechanicalReduction>1</mechanicalReduction>
    </actuator>
  </transmission>
  <transmission name="tran1">
    <type>transmission_interface/SimpleTransmission</type>
    <joint name="hand_l_thumb_joint1">
      <hardwareInterface>hardware_interface/PositionJointInterface</hardwareInterface>
    </joint>
    <actuator name="motor1">
      <hardwareInterface>hardware_interface/PositionJointInterface</hardwareInterface>
      <mechanicalReduction>1</mechanicalReduction>
    </actuator>
  </transmission>
  <transmission name="tran1">
    <type>transmission_interface/SimpleTransmission</type>
    <joint name="hand_l_index_joint1">
      <hardwareInterface>hardware_interface/PositionJointInterface</hardwareInterface>
    </joint>
    <actuator name="motor1">
      <hardwareInterface>hardware_interface/PositionJointInterface</hardwareInterface>
      <mechanicalReduction>1</mechanicalReduction>
    </actuator>
  </transmission>
  <transmission name="tran1">
    <type>transmission_interface/SimpleTransmission</type>
    <joint name="hand_l_middle_joint1">
      <hardwareInterface>hardware_interface/PositionJointInterface</hardwareInterface>
    </joint>
    <actuator name="motor1">
      <hardwareInterface>hardware_interface/PositionJointInterface</hardwareInterface>
      <mechanicalReduction>1</mechanicalReduction>
    </actuator>
  </transmission>
  <transmission name="tran1">
    <type>transmission_interface/SimpleTransmission</type>
    <joint name="hand_l_ring_joint1">
      <hardwareInterface>hardware_interface/PositionJointInterface</hardwareInterface>
    </joint>
    <actuator name="motor1">
      <hardwareInterface>hardware_interface/PositionJointInterface</hardwareInterface>
      <mechanicalReduction>1</mechanicalReduction>
    </actuator>
  </transmission>
  <transmission name="tran1">
    <type>transmission_interface/SimpleTransmission</type>
    <joint name="hand_l_little_joint1">
      <hardwareInterface>hardware_interface/PositionJointInterface</hardwareInterface>
    </joint>
    <actuator name="motor1">
      <hardwareInterface>hardware_interface/PositionJointInterface</hardwareInterface>
      <mechanicalReduction>1</mechanicalReduction>
    </actuator>
  </transmission>
  <gazebo>
    <plugin filename="libroboticsgroup_gazebo_mimic_joint_plugin.so" name="hand_l_thumb_joint2_mimic_joint_plugin">
      <joint>hand_l_thumb_joint1</joint>
      <mimicJoint>hand_l_thumb_joint2</mimicJoint>
      <hasPID/>
      <multiplier>1.822</multiplier>
      <offset>0</offset>
      <sensitiveness>0.0</sensitiveness>
      <maxEffort>10.0</maxEffort>
    </plugin>
  </gazebo>
  <gazebo>
    <plugin filename="libroboticsgroup_gazebo_mimic_joint_plugin.so" name="hand_l_thumb_joint3_mimic_joint_plugin">
      <joint>hand_l_thumb_joint2</joint>
      <mimicJoint>hand_l_thumb_joint3</mimicJoint>
      <hasPID/>
      <multiplier>0.7557</multiplier>
      <offset>0</offset>
      <sensitiveness>0.0</sensitiveness>
      <maxEffort>10.0</maxEffort>
    </plugin>
  </gazebo>
  <gazebo>
    <plugin filename="libroboticsgroup_gazebo_mimic_joint_plugin.so" name="left_index_joint2_mimic_joint_plugin">
      <joint>hand_l_index_joint1</joint>
      <mimicJoint>hand_l_index_joint2</mimicJoint>
      <hasPID/>
      <multiplier>1.0901</multiplier>
      <offset>0</offset>
      <sensitiveness>0.0</sensitiveness>
      <maxEffort>10.0</maxEffort>
    </plugin>
  </gazebo>
  <gazebo>
    <plugin filename="libroboticsgroup_gazebo_mimic_joint_plugin.so" name="left_middle_joint2_mimic_joint_plugin">
      <joint>hand_l_middle_joint1</joint>
      <mimicJoint>hand_l_middle_joint2</mimicJoint>
      <hasPID/>
      <multiplier>1.0901</multiplier>
      <offset>0</offset>
      <sensitiveness>0.0</sensitiveness>
      <maxEffort>10.0</maxEffort>
    </plugin>
  </gazebo>
  <gazebo>
    <plugin filename="libroboticsgroup_gazebo_mimic_joint_plugin.so" name="hand_l_ring_joint2_mimic_joint_plugin">
      <joint>hand_l_ring_joint1</joint>
      <mimicJoint>hand_l_ring_joint2</mimicJoint>
      <hasPID/>
      <multiplier>1.0901</multiplier>
      <offset>0</offset>
      <sensitiveness>0.0</sensitiveness>
      <maxEffort>10.0</maxEffort>
    </plugin>
  </gazebo>
  <gazebo>
    <plugin filename="libroboticsgroup_gazebo_mimic_joint_plugin.so" name="hand_l_little_joint2_mimic_joint_plugin">
      <joint>hand_l_little_joint1</joint>
      <mimicJoint>hand_l_little_joint2</mimicJoint>
      <hasPID/>
      <multiplier>1.0901</multiplier>
      <offset>0</offset>
      <sensitiveness>0.0</sensitiveness>
      <maxEffort>10.0</maxEffort>
    </plugin>
  </gazebo>
  <joint name="idx91_ee_r_joint" type="fixed">
    <parent link="arm_r_end_link"/>
    <child link="hand_r_base_link"/>
    <origin rpy="0 0 0" xyz="0 0 0"/>
    <axis xyz="0.0 0.0 0.0"/>
  </joint>
  <link name="hand_r_base_link">
    <inertial>
      <origin rpy="0 0 0" xyz="-0.00174346841701916 -0.00527579194314928 0.0491475460895892"/>
      <mass value="0.34872"/>
      <inertia ixx="8.73156029524248E-05" ixy="-2.76454788715318E-07" ixz="-6.56394653650542E-07" iyy="0.00013139692405234" iyz="-2.87478350015867E-06" izz="6.85856479957296E-05"/>
    </inertial>
    <visual>
      <origin rpy="0 0 0" xyz="0 0 0"/>
      <geometry>
        <mesh filename="package://genie_robot_description/meshes/skillhands6/R_base_link.STL"/>
      </geometry>
      <material name="">
        <color rgba="0.792156862745098 0.819607843137255 0.933333333333333 1"/>
      </material>
    </visual>
    <collision>
      <origin rpy="0 0 0" xyz="0 0 0"/>
      <geometry>
        <mesh filename="package://genie_robot_description/meshes/skillhands6/R_base_link.STL"/>
      </geometry>
    </collision>
  </link>
  <link name="hand_r_thumb_link0">
    <inertial>
      <origin rpy="0 0 0" xyz="-0.00794385183139725 0.000525120612119151 0.00647353069427367"/>
      <mass value="0.00293"/>
      <inertia ixx="9.46681111469513E-08" ixy="2.82870154716105E-09" ixz="6.48803833821274E-10" iyy="1.37273777260403E-07" iyz="-4.31486298309418E-11" izz="9.49138662594884E-08"/>
    </inertial>
    <visual>
      <origin rpy="0 0 0" xyz="0 0 0"/>
      <geometry>
        <mesh filename="package://genie_robot_description/meshes/skillhands6/R_thumb_swing.STL"/>
      </geometry>
      <material name="">
        <color rgba="0.827450980392157 0.83921568627451 0.827450980392157 1"/>
      </material>
    </visual>
    <collision>
      <origin rpy="0 0 0" xyz="0 0 0"/>
      <geometry>
        <mesh filename="package://genie_robot_description/meshes/skillhands6/R_thumb_swing.STL"/>
      </geometry>
    </collision>
  </link>
  <joint name="hand_r_thumb_joint0" type="revolute">
    <origin rpy="0 0 0" xyz="-0.028697 0.021402 0.020504"/>
    <parent link="hand_r_base_link"/>
    <child link="hand_r_thumb_link0"/>
    <axis xyz="0 0 -1"/>
    <limit effort="10" lower="0" upper="2.286" velocity="1"/>
  </joint>
  <link name="hand_r_thumb_link1">
    <inertial>
      <origin rpy="0 0 0" xyz="0.0259002099345081 0.0127439796878742 -1.99493196570838E-05"/>
      <mass value="0.04967"/>
      <inertia ixx="3.31629342056679E-06" ixy="-8.26036894806839E-07" ixz="-5.55467469886505E-10" iyy="3.39227446692523E-06" iyz="-2.74467395508138E-09" izz="5.78826252617142E-06"/>
    </inertial>
    <visual>
      <origin rpy="0 0 0" xyz="0 0 0"/>
      <geometry>
        <mesh filename="package://genie_robot_description/meshes/skillhands6/R_thumb_1.STL"/>
      </geometry>
      <material name="">
        <color rgba="0.792156862745098 0.819607843137255 0.933333333333333 1"/>
      </material>
    </visual>
    <collision>
      <origin rpy="0 0 0" xyz="0 0 0"/>
      <geometry>
        <mesh filename="package://genie_robot_description/meshes/skillhands6/R_thumb_1.STL"/>
      </geometry>
    </collision>
  </link>
  <joint name="hand_r_thumb_joint1" type="revolute">
    <origin rpy="1.5708 0 3.0756" xyz="-0.013367 0.00088357 0.0052468"/>
    <parent link="hand_r_thumb_link0"/>
    <child link="hand_r_thumb_link1"/>
    <axis xyz="0 0 1"/>
    <limit effort="10" lower="0" upper="0.4765" velocity="1"/>
  </joint>
  <link name="hand_r_thumb_link2">
    <inertial>
      <origin rpy="0 0 0" xyz="0.0112938280283933 0.00190048762153883 -0.00768932284017045"/>
      <mass value="0.00955"/>
      <inertia ixx="4.33768382054372E-07" ixy="-3.01457326686904E-08" ixz="-2.51640808750991E-11" iyy="3.41487853815651E-07" iyz="-8.87078510861614E-11" izz="4.77629558482899E-07"/>
    </inertial>
    <visual>
      <origin rpy="0 0 0" xyz="0 0 0"/>
      <geometry>
        <mesh filename="package://genie_robot_description/meshes/skillhands6/R_thumb_2.STL"/>
      </geometry>
      <material name="">
        <color rgba="0.792156862745098 0.819607843137255 0.933333333333333 1"/>
      </material>
    </visual>
    <collision>
      <origin rpy="0 0 0" xyz="0 0 0"/>
      <geometry>
        <mesh filename="package://genie_robot_description/meshes/skillhands6/R_thumb_2.STL"/>
      </geometry>
    </collision>
  </link>
  <joint name="hand_r_thumb_joint2" type="revolute">
    <origin rpy="0 0 0" xyz="0.0389415822724812 0.0379042246431505 0.00770000000000043"/>
    <parent link="hand_r_thumb_link1"/>
    <child link="hand_r_thumb_link2"/>
    <axis xyz="0 0 1"/>
    <limit effort="10" lower="0" upper="0.888" velocity="1.822"/>
    <!--<mimic joint="hand_r_thumb_joint1" multiplier="1.822" offset="0"/>-->
  </joint>
  <link name="hand_r_thumb_link3">
    <inertial>
      <origin rpy="0 0 0" xyz="0.00856534554797862 0.00586022128255342 -0.00530182283153385"/>
      <mass value="0.01039"/>
      <inertia ixx="4.15501197420746E-07" ixy="-1.25284733421831E-07" ixz="1.14020106815917E-10" iyy="2.49677035533967E-07" iyz="1.89120892374144E-10" izz="4.96219470794644E-07"/>
    </inertial>
    <visual>
      <origin rpy="0 0 0" xyz="0 0 0"/>
      <geometry>
        <mesh filename="package://genie_robot_description/meshes/skillhands6/R_thumb_3.STL"/>
      </geometry>
      <material name="">
        <color rgba="1 1 1 1"/>
      </material>
    </visual>
    <collision>
      <origin rpy="0 0 0" xyz="0 0 0"/>
      <geometry>
        <mesh filename="package://genie_robot_description/meshes/skillhands6/R_thumb_3.STL"/>
      </geometry>
    </collision>
  </link>
  <joint name="hand_r_thumb_joint3" type="revolute">
    <origin rpy="0 0 0" xyz="0.01728 0.014743 -0.0024"/>
    <parent link="hand_r_thumb_link2"/>
    <child link="hand_r_thumb_link3"/>
    <axis xyz="0 0 1"/>
    <limit effort="10" lower="0" upper="0.705" velocity="1.3769"/>
    <!--<mimic joint="hand_r_thumb_joint2" multiplier="0.7557" offset="0"/>-->
  </joint>
  <link name="hand_r_index_link1">
    <inertial>
      <origin rpy="0 0 0" xyz="0.00224105284932037 0.012077244969504 -0.0060501936211354"/>
      <mass value="0.01247"/>
      <inertia ixx="6.7083586478962E-07" ixy="-6.24488990875019E-09" ixz="3.08577901734797E-12" iyy="2.67077182124417E-07" iyz="6.36376851728619E-12" izz="6.64566137309628E-07"/>
    </inertial>
    <visual>
      <origin rpy="0 0 0" xyz="0 0 0"/>
      <geometry>
        <mesh filename="package://genie_robot_description/meshes/skillhands6/R_index_1.STL"/>
      </geometry>
      <material name="">
        <color rgba="0.792156862745098 0.819607843137255 0.933333333333333 1"/>
      </material>
    </visual>
    <collision>
      <origin rpy="0 0 0" xyz="0 0 0"/>
      <geometry>
        <mesh filename="package://genie_robot_description/meshes/skillhands6/R_index_1.STL"/>
      </geometry>
    </collision>
  </link>
  <joint name="hand_r_index_joint1" type="revolute">
    <origin rpy="1.6319 -0.04887 -1.5708" xyz="-0.034163 0.00015626 0.10177"/>
    <parent link="hand_r_base_link"/>
    <child link="hand_r_index_link1"/>
    <axis xyz="0 0 1"/>
    <limit effort="10" lower="0" upper="1.566" velocity="1"/>
  </joint>
  <link name="hand_r_index_link2">
    <inertial>
      <origin rpy="0 0 0" xyz="0.00267181156648408 0.0187445889538955 -0.00504998556104182"/>
      <mass value="0.00996"/>
      <inertia ixx="8.55148442316881E-07" ixy="8.71729684204069E-08" ixz="-8.24415168858219E-14" iyy="1.37439550017429E-07" iyz="-2.39445035228549E-12" izz="8.7133999943214E-07"/>
    </inertial>
    <visual>
      <origin rpy="0 0 0" xyz="0 0 0"/>
      <geometry>
        <mesh filename="package://genie_robot_description/meshes/skillhands6/R_index_2.STL"/>
      </geometry>
      <material name="">
        <color rgba="1 1 1 1"/>
      </material>
    </visual>
    <collision>
      <origin rpy="0 0 0" xyz="0 0 0"/>
      <geometry>
        <mesh filename="package://genie_robot_description/meshes/skillhands6/R_index_2.STL"/>
      </geometry>
    </collision>
  </link>
  <joint name="hand_r_index_joint2" type="revolute">
    <origin rpy="0 0 0.03665" xyz="-0.00025731 0.032131 -0.001"/>
    <parent link="hand_r_index_link1"/>
    <child link="hand_r_index_link2"/>
    <axis xyz="0 0 1"/>
    <limit effort="10" lower="0" upper="1.753" velocity="1.0901"/>
   <!--<mimic joint="hand_r_index_joint1" multiplier="1.0901" offset="0"/>-->
  </joint>
  <link name="hand_r_middle_link1">
    <inertial>
      <origin rpy="0 0 0" xyz="0.00224109922728143 0.0120773004987843 -0.00605026659163534"/>
      <mass value="0.01247"/>
      <inertia ixx="6.70837166910088E-07" ixy="-6.24455169745287E-09" ixz="3.25321014718543E-12" iyy="2.67075608382375E-07" iyz="7.72285454063169E-12" izz="6.64566599226699E-07"/>
    </inertial>
    <visual>
      <origin rpy="0 0 0" xyz="0 0 0"/>
      <geometry>
        <mesh filename="package://genie_robot_description/meshes/skillhands6/R_middle_1.STL"/>
      </geometry>
      <material name="">
        <color rgba="0.792156862745098 0.819607843137255 0.933333333333333 1"/>
      </material>
    </visual>
    <collision>
      <origin rpy="0 0 0" xyz="0 0 0"/>
      <geometry>
        <mesh filename="package://genie_robot_description/meshes/skillhands6/R_middle_1.STL"/>
      </geometry>
    </collision>
  </link>
  <joint name="hand_r_middle_joint1" type="revolute">
    <origin rpy="1.5708 -0.04887 -1.5708" xyz="-0.014247 0.00015626 0.1026"/>
    <parent link="hand_r_base_link"/>
    <child link="hand_r_middle_link1"/>
    <axis xyz="0 0 1"/>
    <limit effort="10" lower="0" upper="1.566" velocity="1"/>
  </joint>
  <link name="hand_r_middle_link2">
    <inertial>
      <origin rpy="0 0 0" xyz="0.00298222684069903 0.0208035344929268 -0.00505001299185808"/>
      <mass value="0.01048"/>
      <inertia ixx="1.14490560231061E-06" ixy="9.72401476943198E-08" ixz="1.3517205790896E-13" iyy="1.43751808502962E-07" iyz="-2.47497784308553E-12" izz="1.15530613342501E-06"/>
    </inertial>
    <visual>
      <origin rpy="0 0 0" xyz="0 0 0"/>
      <geometry>
        <mesh filename="package://genie_robot_description/meshes/skillhands6/R_middle_2.STL"/>
      </geometry>
      <material name="">
        <color rgba="1 1 1 1"/>
      </material>
    </visual>
    <collision>
      <origin rpy="0 0 0" xyz="0 0 0"/>
      <geometry>
        <mesh filename="package://genie_robot_description/meshes/skillhands6/R_middle_2.STL"/>
      </geometry>
    </collision>
  </link>
  <joint name="hand_r_middle_joint2" type="revolute">
    <origin rpy="0 0 0.03665" xyz="-0.000257313524408706 0.0321313914917268 -0.000999999999997433"/>
    <parent link="hand_r_middle_link1"/>
    <child link="hand_r_middle_link2"/>
    <axis xyz="0 0 1"/>
    <limit effort="10" lower="0" upper="1.753" velocity="1.0901"/>
    <!--<mimic joint="hand_r_middle_joint1" multiplier="1.0901" offset="0"/>-->
  </joint>
  <link name="hand_r_ring_link1">
    <inertial>
      <origin rpy="0 0 0" xyz="0.00224111083051005 0.0120773228749342 -0.00605025463459374"/>
      <mass value="0.01247"/>
      <inertia ixx="6.70838404636804E-07" ixy="-6.24505446614477E-09" ixz="3.11377919594888E-12" iyy="2.67075452784363E-07" iyz="6.97432649840291E-12" izz="6.64567590491197E-07"/>
    </inertial>
    <visual>
      <origin rpy="0 0 0" xyz="0 0 0"/>
      <geometry>
        <mesh filename="package://genie_robot_description/meshes/skillhands6/R_ring_1.STL"/>
      </geometry>
      <material name="">
        <color rgba="0.792156862745098 0.819607843137255 0.933333333333333 1"/>
      </material>
    </visual>
    <collision>
      <origin rpy="0 0 0" xyz="0 0 0"/>
      <geometry>
        <mesh filename="package://genie_robot_description/meshes/skillhands6/R_ring_1.STL"/>
      </geometry>
    </collision>
  </link>
  <joint name="hand_r_ring_joint1" type="revolute">
    <origin rpy="1.5184 -0.04887 -1.5708" xyz="0.0064906 0.00015626 0.10242"/>
    <parent link="hand_r_base_link"/>
    <child link="hand_r_ring_link1"/>
    <axis xyz="0 0 1"/>
    <limit effort="10" lower="0" upper="1.566" velocity="1"/>
  </joint>
  <link name="hand_r_ring_link2">
    <inertial>
      <origin rpy="0 0 0" xyz="0.00298222724294862 0.0208035302665959 -0.00505000729887283"/>
      <mass value="0.01048"/>
      <inertia ixx="1.14490597705472E-06" ixy="9.724016633507E-08" ixz="1.8724939827074E-14" iyy="1.43751909738487E-07" iyz="-2.55418863081498E-12" izz="1.15530647485239E-06"/>
    </inertial>
    <visual>
      <origin rpy="0 0 0" xyz="0 0 0"/>
      <geometry>
        <mesh filename="package://genie_robot_description/meshes/skillhands6/R_ring_2.STL"/>
      </geometry>
      <material name="">
        <color rgba="1 1 1 1"/>
      </material>
    </visual>
    <collision>
      <origin rpy="0 0 0" xyz="0 0 0"/>
      <geometry>
        <mesh filename="package://genie_robot_description/meshes/skillhands6/R_ring_2.STL"/>
      </geometry>
    </collision>
  </link>
  <joint name="hand_r_ring_joint2" type="revolute">
    <origin rpy="0 0 0.03665" xyz="-0.00025731 0.032131 -0.001"/>
    <parent link="hand_r_ring_link1"/>
    <child link="hand_r_ring_link2"/>
    <axis xyz="0 0 1"/>
    <limit effort="10" lower="0" upper="1.753" velocity="1.0901"/>
    <!--<mimic joint="hand_r_ring_joint1" multiplier="1.0901" offset="0"/>-->
  </joint>
  <link name="hand_r_little_link1">
    <inertial>
      <origin rpy="0 0 0" xyz="0.00224116685703836 0.0120774556144769 -0.00605021177667593"/>
      <mass value="0.01247"/>
      <inertia ixx="6.70846058569314E-07" ixy="-6.24765025269437E-09" ixz="2.14363990209694E-12" iyy="2.67077034128326E-07" iyz="4.49364771164151E-12" izz="6.64575163698131E-07"/>
    </inertial>
    <visual>
      <origin rpy="0 0 0" xyz="0 0 0"/>
      <geometry>
        <mesh filename="package://genie_robot_description/meshes/skillhands6/R_little_1.STL"/>
      </geometry>
      <material name="">
        <color rgba="0.792156862745098 0.819607843137255 0.933333333333333 1"/>
      </material>
    </visual>
    <collision>
      <origin rpy="0 0 0" xyz="0 0 0"/>
      <geometry>
        <mesh filename="package://genie_robot_description/meshes/skillhands6/R_little_1.STL"/>
      </geometry>
    </collision>
  </link>
  <joint name="hand_r_little_joint1" type="revolute">
    <origin rpy="1.46607657167534 -0.04887 -1.57079632679191" xyz="0.0267358938400829 0.000156259167782558 0.101113845897859"/>
    <parent link="hand_r_base_link"/>
    <child link="hand_r_little_link1"/>
    <axis xyz="0 0 1"/>
    <limit effort="10" lower="0" upper="1.566" velocity="1"/>
  </joint>
  <link name="hand_r_little_link2">
    <inertial>
      <origin rpy="0 0 0" xyz="0.00379562052007763 0.0143619415198121 -0.00504990649038004"/>
      <mass value="0.00792"/>
      <inertia ixx="4.4165258349127E-07" ixy="2.35241296174338E-08" ixz="-1.03160129872049E-12" iyy="9.72293330312645E-08" iyz="3.91885258086726E-12" izz="4.50179231370321E-07"/>
    </inertial>
    <visual>
      <origin rpy="0 0 0" xyz="0 0 0"/>
      <geometry>
        <mesh filename="package://genie_robot_description/meshes/skillhands6/R_little_2.STL"/>
      </geometry>
      <material name="">
        <color rgba="1 1 1 1"/>
      </material>
    </visual>
    <collision>
      <origin rpy="0 0 0" xyz="0 0 0"/>
      <geometry>
        <mesh filename="package://genie_robot_description/meshes/skillhands6/R_little_2.STL"/>
      </geometry>
    </collision>
  </link>
  <joint name="hand_r_little_joint2" type="revolute">
    <origin rpy="0 0 0.03665" xyz="-0.00025731 0.032131 -0.001"/>
    <parent link="hand_r_little_link1"/>
    <child link="hand_r_little_link2"/>
    <axis xyz="0 0 1"/>
    <limit effort="10" lower="0" upper="1.753" velocity="1.0901"/>
   <!--<mimic joint="hand_r_little_joint1" multiplier="1.0901" offset="0"/>-->
  </joint>
  <gazebo>
    <plugin filename="libgazebo_ros_control.so" name="gazebo_ros_control">
      <robotNamespace>/</robotNamespace>
      <legacyModeNS>true</legacyModeNS>
      <controlPeriod>0.001</controlPeriod>
      <robotSimType>gazebo_ros_control/DefaultRobotHWSim</robotSimType>
    </plugin>
  </gazebo>
  <transmission name="tran1">
    <type>transmission_interface/SimpleTransmission</type>
    <joint name="hand_r_thumb_joint0">
      <hardwareInterface>hardware_interface/PositionJointInterface</hardwareInterface>
    </joint>
    <actuator name="motor1">
      <hardwareInterface>hardware_interface/PositionJointInterface</hardwareInterface>
      <mechanicalReduction>1</mechanicalReduction>
    </actuator>
  </transmission>
  <transmission name="tran1">
    <type>transmission_interface/SimpleTransmission</type>
    <joint name="hand_r_thumb_joint1">
      <hardwareInterface>hardware_interface/PositionJointInterface</hardwareInterface>
    </joint>
    <actuator name="motor1">
      <hardwareInterface>hardware_interface/PositionJointInterface</hardwareInterface>
      <mechanicalReduction>1</mechanicalReduction>
    </actuator>
  </transmission>
  <transmission name="tran1">
    <type>transmission_interface/SimpleTransmission</type>
    <joint name="hand_r_index_joint1">
      <hardwareInterface>hardware_interface/PositionJointInterface</hardwareInterface>
    </joint>
    <actuator name="motor1">
      <hardwareInterface>hardware_interface/PositionJointInterface</hardwareInterface>
      <mechanicalReduction>1</mechanicalReduction>
    </actuator>
  </transmission>
  <transmission name="tran1">
    <type>transmission_interface/SimpleTransmission</type>
    <joint name="hand_r_middle_joint1">
      <hardwareInterface>hardware_interface/PositionJointInterface</hardwareInterface>
    </joint>
    <actuator name="motor1">
      <hardwareInterface>hardware_interface/PositionJointInterface</hardwareInterface>
      <mechanicalReduction>1</mechanicalReduction>
    </actuator>
  </transmission>
  <transmission name="tran1">
    <type>transmission_interface/SimpleTransmission</type>
    <joint name="hand_r_ring_joint1">
      <hardwareInterface>hardware_interface/PositionJointInterface</hardwareInterface>
    </joint>
    <actuator name="motor1">
      <hardwareInterface>hardware_interface/PositionJointInterface</hardwareInterface>
      <mechanicalReduction>1</mechanicalReduction>
    </actuator>
  </transmission>
  <transmission name="tran1">
    <type>transmission_interface/SimpleTransmission</type>
    <joint name="hand_r_little_joint1">
      <hardwareInterface>hardware_interface/PositionJointInterface</hardwareInterface>
    </joint>
    <actuator name="motor1">
      <hardwareInterface>hardware_interface/PositionJointInterface</hardwareInterface>
      <mechanicalReduction>1</mechanicalReduction>
    </actuator>
  </transmission>
  <gazebo>
    <plugin filename="libroboticsgroup_gazebo_mimic_joint_plugin.so" name="hand_r_thumb_joint2_mimic_joint_plugin">
      <joint>hand_r_thumb_joint1</joint>
      <mimicJoint>hand_r_thumb_joint2</mimicJoint>
      <hasPID/>
      <multiplier>1.822</multiplier>
      <offset>0</offset>
      <sensitiveness>0.0</sensitiveness>
      <maxEffort>10.0</maxEffort>
    </plugin>
  </gazebo>
  <gazebo>
    <plugin filename="libroboticsgroup_gazebo_mimic_joint_plugin.so" name="hand_r_thumb_joint3_mimic_joint_plugin">
      <joint>hand_r_thumb_joint2</joint>
      <mimicJoint>hand_r_thumb_joint3</mimicJoint>
      <hasPID/>
      <multiplier>0.7557</multiplier>
      <offset>0</offset>
      <sensitiveness>0.0</sensitiveness>
      <maxEffort>10.0</maxEffort>
    </plugin>
  </gazebo>
  <gazebo>
    <plugin filename="libroboticsgroup_gazebo_mimic_joint_plugin.so" name="left_index_joint2_mimic_joint_plugin">
      <joint>hand_r_index_joint1</joint>
      <mimicJoint>hand_r_index_joint2</mimicJoint>
      <hasPID/>
      <multiplier>1.0901</multiplier>
      <offset>0</offset>
      <sensitiveness>0.0</sensitiveness>
      <maxEffort>10.0</maxEffort>
    </plugin>
  </gazebo>
  <gazebo>
    <plugin filename="libroboticsgroup_gazebo_mimic_joint_plugin.so" name="left_middle_joint2_mimic_joint_plugin">
      <joint>hand_r_middle_joint1</joint>
      <mimicJoint>hand_r_middle_joint2</mimicJoint>
      <hasPID/>
      <multiplier>1.0901</multiplier>
      <offset>0</offset>
      <sensitiveness>0.0</sensitiveness>
      <maxEffort>10.0</maxEffort>
    </plugin>
  </gazebo>
  <gazebo>
    <plugin filename="libroboticsgroup_gazebo_mimic_joint_plugin.so" name="hand_r_ring_joint2_mimic_joint_plugin">
      <joint>hand_r_ring_joint1</joint>
      <mimicJoint>hand_r_ring_joint2</mimicJoint>
      <hasPID/>
      <multiplier>1.0901</multiplier>
      <offset>0</offset>
      <sensitiveness>0.0</sensitiveness>
      <maxEffort>10.0</maxEffort>
    </plugin>
  </gazebo>
  <gazebo>
    <plugin filename="libroboticsgroup_gazebo_mimic_joint_plugin.so" name="hand_r_little_joint2_mimic_joint_plugin">
      <joint>hand_r_little_joint1</joint>
      <mimicJoint>hand_r_little_joint2</mimicJoint>
      <hasPID/>
      <multiplier>1.0901</multiplier>
      <offset>0</offset>
      <sensitiveness>0.0</sensitiveness>
      <maxEffort>10.0</maxEffort>
    </plugin>
  </gazebo>
</robot>
